Workbook

Sheet Half Terms - Template
B1: Half Terms
A6: — | B6: 46321 | C6: 46322 | D6: 46323 | E6: 46324 | F6: 46325 | G6: 46328 | H6: 46329 | I6: 46330 | J6: 46331 | K6: 46332 | L6: —
A16: — | B16: 46377 | C16: 46378 | D16: 46379 | E16: 46380 | F16: 46381 | G16: 46384 | H16: 46385 | I16: 46386 | J16: 46387 | K16: 46388 | L16: —
A26: — | B26: 46433 | C26: 46434 | D26: 46435 | E26: 46436 | F26: 46437 | L26: —
A36: — | B36: 46475 | C36: 46476 | D36: 46477 | E36: 46478 | F36: 46479 | G36: 46482 | H36: 46483 | I36: 46484 | J36: 46485 | K36: 46486 | L36: —
A46: — | B46: 46538 | C46: 46539 | D46: 46540 | E46: 46541 | F46: 46542 | L46: —

Sheet Week A - Template
B1: WEEK A | D1: N21 | E1: N22 | F1: N23 | G1: N24 | H1: N25 | I1: N26
C2: Teacher | D2: J Barnes | E2: A Okafor | F2: - | G2: S Whitfield | H2: M Devlin | I2: —
C3: No of PCs | D3: 30 | E3: 28 | F3: 15 | G3: 32 | H3: 24 | I3: 12
C4: Telephone | D4: 2101 | E4: 2102 | F4: 0x10 | G4: 2104 | H4: 2105 | I4: 2106
B6: 46265 | C6: Registration
C7: Period 1 | D7: 10E/Cs | E7: 7A/Cs | F7: 9F/It | G7: 12/Cs1 | I7: 11B/It
C8: Period 2 | E8: 8D/It | F8: 11B/It | G8: 7B/Cs | H8: 10D/Bs
C9: Break 1
C10: Period 3 | D10: 7B/Cs | F10: 13/It2 | G10: 9E/It | H10: 11C/Bs | I10: 8C/Bs
C11: Period 4 | D11: 9E/It | E11: 11C/Bs | G11: 10E/Cs | H11: 7A/Cs | I11: 9F/It
C12: Break 2
C13: Period 5 | D13: 10E/Cs | E13: 7A/Cs | F13: 9F/It | H13: 8D/It | I13: 11B/It
C14: Period 6 | D14: 12/Cs1 | E14: 8D/It | F14: 11B/It | G14: 7B/Cs | I14: 13/It2
B16: 46266 | C16: Registration
C17: Period 1 | D17: 8C/Bs | E17: 10E/Cs | F17: 7A/Cs | H17: 12/Cs1 | I17: 8D/It
C18: Period 2 | D18: 9F/It | E18: 12/Cs1 | F18: 8D/It | G18: 11B/It | I18: 10D/Bs
C19: Break 1
C20: Period 3 | E20: 7B/Cs | F20: 10D/Bs | G20: 13/It2 | H20: 9E/It
C21: Period 4 | D21: 13/It2 | F21: 11C/Bs | G21: 8C/Bs | H21: 10E/Cs | I21: 7A/Cs
C22: Break 2
C23: Period 5 | D23: 8C/Bs | E23: 10E/Cs | G23: 9F/It | H23: 12/Cs1 | I23: 8D/It
C24: Period 6 | D24: 9F/It | E24: 12/Cs1 | F24: 8D/It | H24: 7B/Cs | I24: 10D/Bs
B26: 46267 | C26: Registration
C27: Period 1 | D27: 11C/Bs | E27: 8C/Bs | G27: 7A/Cs | H27: 9F/It | I27: 12/Cs1
C28: Period 2 | D28: 7A/Cs | E28: 9F/It | F28: 12/Cs1 | H28: 11B/It | I28: 7B/Cs
C29: Break 1
C30: Period 3 | D30: 8D/It | E30: 11B/It | F30: 7B/Cs | G30: 10D/Bs | I30: 9E/It
C31: Period 4 | E31: 13/It2 | F31: 9E/It | G31: 11C/Bs | H31: 8C/Bs
C32: Break 2
C33: Period 5 | D33: 11C/Bs | F33: 10E/Cs | G33: 7A/Cs | H33: 9F/It | I33: 12/Cs1
C34: Period 6 | D34: 7A/Cs | E34: 9F/It | G34: 8D/It | H34: 11B/It | I34: 7B/Cs
B36: 46268 | C36: Registration
C37: Period 1 | D37: 9E/It | E37: - | F37: 8C/Bs | G37: 10E/Cs | H37: 7A/Cs | I37: 9F/It
C38: Period 2 | D38: 10E/Cs | E38: 7A/Cs | G38: 12/Cs1 | H38: 8D/It | I38: 11B/It
C39: Break 1
C40: Period 3 | D40: 12/Cs1 | E40: 8D/It | F40: 11B/It | H40: 10D/Bs | I40: 13/It2
C41: Period 4 | D41: 7B/Cs | E41: 10D/Bs | F41: 13/It2 | G41: 9E/It | I41: 8C/Bs
C42: Break 2
C43: Period 5 | E43: 11C/Bs | F43: 8C/Bs | G43: 10E/Cs | H43: 7A/Cs
C44: Period 6 | D44: 10E/Cs | F44: 9F/It | G44: 12/Cs1 | H44: 8D/It | I44: 11B/It
...

Sheet Week B - Template
B1: WEEK B | D1: N21 | E1: N22 | F1: N23 | G1: N24 | H1: N25 | I1: N26
C2: Teacher | D2: J Barnes | E2: A Okafor | F2: - | G2: S Whitfield | H2: M Devlin | I2: —
C3: No of PCs | D3: 30 | E3: 28 | F3: 15 | G3: 32 | H3: 24 | I3: 12
C4: Telephone | D4: 2101 | E4: 2102 | F4: 0x10 | G4: 2104 | H4: 2105 | I4: 2106
B6: 46272 | C6: Registration
C7: Period 1 | D7: 11B/It | E7: 7B/Cs | F7: 10D/Bs | H7: 9E/It | I7: 11C/Bs
C8: Period 2 | D8: 13/It2 | E8: 9E/It | F8: 11C/Bs | G8: 8C/Bs | I8: 7A/Cs
C9: Break 1
C10: Period 3 | E10: 10E/Cs | F10: 7A/Cs | G10: 9F/It | H10: 12/Cs1
C11: Period 4 | D11: 9F/It | F11: 8D/It | G11: 11B/It | H11: 7B/Cs | I11: 10D/Bs
C12: Break 2
C13: Period 5 | D13: 11B/It | E13: 7B/Cs | G13: 13/It2 | H13: 9E/It | I13: 11C/Bs
C14: Period 6 | D14: 13/It2 | E14: 9E/It | F14: 11C/Bs | H14: 10E/Cs | I14: 7A/Cs
B16: 46273 | C16: Registration
C17: Period 1 | D17: 8D/It | E17: 11B/It | G17: 10D/Bs | H17: 13/It2 | I17: 9E/It
C18: Period 2 | D18: 10D/Bs | E18: 13/It2 | F18: 9E/It | H18: 8C/Bs | I18: 10E/Cs
C19: Break 1
C20: Period 3 | D20: 11C/Bs | E20: 8C/Bs | F20: 10E/Cs | G20: 7A/Cs | I20: 12/Cs1
C21: Period 4 | E21: 9F/It | F21: 12/Cs1 | G21: 8D/It | H21: 11B/It
C22: Break 2
C23: Period 5 | D23: 8D/It | F23: 7B/Cs | G23: 10D/Bs | H23: 13/It2 | I23: 9E/It
C24: Period 6 | D24: 10D/Bs | E24: 13/It2 | G24: 11C/Bs | H24: 8C/Bs | I24: 10E/Cs
B26: 46274 | C26: Registration
C27: Period 1 | D27: 12/Cs1 | F27: 11B/It | G27: 7B/Cs | H27: 10D/Bs | I27: 13/It2
C28: Period 2 | D28: 7B/Cs | E28: 10D/Bs | G28: 9E/It | H28: 11C/Bs | I28: 8C/Bs
C29: Break 1
C30: Period 3 | D30: 9E/It | E30: 11C/Bs | F30: 8C/Bs | H30: 7A/Cs | I30: 9F/It
C31: Period 4 | D31: 10E/Cs | E31: 7A/Cs | F31: 9F/It | G31: 12/Cs1 | I31: 11B/It
C32: Break 2
C33: Period 5 | E33: 8D/It | F33: 11B/It | G33: 7B/Cs | H33: 10D/Bs
C34: Period 6 | D34: 7B/Cs | F34: 13/It2 | G34: 9E/It | H34: 11C/Bs | I34: 8C/Bs
B36: 46275 | C36: Registration
C37: Period 1 | E37: 12/Cs1 | F37: 8D/It | G37: 11B/It | H37: 7B/Cs
C38: Period 2 | D38: 11B/It | F38: 10D/Bs | G38: 13/It2 | H38: 9E/It | I38: 11C/Bs
C39: Break 1
C40: Period 3 | D40: 13/It2 | E40: 9E/It | G40: 8C/Bs | H40: 10E/Cs | I40: 7A/Cs
C41: Period 4 | D41: 8C/Bs | E41: 10E/Cs | F41: 7A/Cs | H41: 12/Cs1 | I41: 8D/It
C42: Break 2
C43: Period 5 | D43: 9F/It | E43: 12/Cs1 | F43: 8D/It | G43: 11B/It | I43: 10D/Bs
C44: Period 6 | E44: 7B/Cs | F44: 10D/Bs | G44: 13/It2 | H44: 9E/It
...

Sheet (A) August 31st - September 4th
B1: WEEK A | D1: N21 | E1: N22 | F1: N23 | G1: N24 | H1: N25 | I1: N26
C2: Teacher | D2: J Barnes | E2: A Okafor | F2: - | G2: S Whitfield | H2: M Devlin | I2: —
C3: No of PCs | D3: 30 | E3: 28 | F3: 15 | G3: 32 | H3: 24 | I3: 12
C4: Telephone | D4: 2101 | E4: 2102 | F4: 0x10 | G4: 2104 | H4: 2105 | I4: 2106
B6: 46265 | C6: Registration
C7: Period 1
C8: Period 2
C9: Break 1
C10: Period 3
C11: Period 4
C12: Break 2
C13: Period 5
C14: Period 6
B16: 46266 | C16: Registration
C17: Period 1
C18: Period 2
C19: Break 1
C20: Period 3
C21: Period 4
C22: Break 2
C23: Period 5
C24: Period 6
B26: 46267 | C26: Registration
C27: Period 1 | D27: =IF('Week A - Template'!D27="","",'Week A - Template'!D27) -> 11C/Bs | E27: =IF('Week A - Template'!E27="","",'Week A - Template'!E27) -> 8C/Bs | F27: =IF('Week A - Template'!F27="","",'Week A - Template'!F27) | G27: =IF('Week A - Template'!G27="","",'Week A - Template'!G27) -> 7A/Cs | H27: =IF('Week A - Template'!H27="","",'Week A - Template'!H27) -> 9F/It | I27: =IF('Week A - Template'!I27="","",'Week A - Template'!I27) -> 12/Cs1
C28: Period 2 | D28: =IF('Week A - Template'!D28="","",'Week A - Template'!D28) -> 7A/Cs | E28: =IF('Week A - Template'!E28="","",'Week A - Template'!E28) -> 9F/It | F28: =IF('Week A - Template'!F28="","",'Week A - Template'!F28) -> 12/Cs1 | G28: =IF('Week A - Template'!G28="","",'Week A - Template'!G28) | H28: =IF('Week A - Template'!H28="","",'Week A - Template'!H28) -> 11B/It | I28: =IF('Week A - Template'!I28="","",'Week A - Template'!I28) -> 7B/Cs
C29: Break 1
C30: Period 3 | D30: =IF('Week A - Template'!D30="","",'Week A - Template'!D30) -> 8D/It | E30: =IF('Week A - Template'!E30="","",'Week A - Template'!E30) -> 11B/It | F30: =IF('Week A - Template'!F30="","",'Week A - Template'!F30) -> 7B/Cs | G30: =IF('Week A - Template'!G30="","",'Week A - Template'!G30) -> 10D/Bs | H30: =IF('Week A - Template'!H30="","",'Week A - Template'!H30) | I30: =IF('Week A - Template'!I30="","",'Week A - Template'!I30) -> 9E/It
C31: Period 4 | D31: =IF('Week A - Template'!D31="","",'Week A - Template'!D31) | E31: =IF('Week A - Template'!E31="","",'Week A - Template'!E31) -> 13/It2 | F31: =IF('Week A - Template'!F31="","",'Week A - Template'!F31) -> 9E/It | G31: =IF('Week A - Template'!G31="","",'Week A - Template'!G31) -> 11C/Bs | H31: =IF('Week A - Template'!H31="","",'Week A - Template'!H31) -> 8C/Bs | I31: =IF('Week A - Template'!I31="","",'Week A - Template'!I31)
C32: Break 2
C33: Period 5 | D33: =IF('Week A - Template'!D33="","",'Week A - Template'!D33) -> 11C/Bs | E33: =IF('Week A - Template'!E33="","",'Week A - Template'!E33) | F33: =IF('Week A - Template'!F33="","",'Week A - Template'!F33) -> 10E/Cs | G33: =IF('Week A - Template'!G33="","",'Week A - Template'!G33) -> 7A/Cs | H33: =IF('Week A - Template'!H33="","",'Week A - Template'!H33) -> 9F/It | I33: =IF('Week A - Template'!I33="","",'Week A - Template'!I33) -> 12/Cs1
C34: Period 6 | D34: =IF('Week A - Template'!D34="","",'Week A - Template'!D34) -> 7A/Cs | E34: =IF('Week A - Template'!E34="","",'Week A - Template'!E34) -> 9F/It | F34: =IF('Week A - Template'!F34="","",'Week A - Template'!F34) | G34: =IF('Week A - Template'!G34="","",'Week A - Template'!G34) -> 8D/It | H34: =IF('Week A - Template'!H34="","",'Week A - Template'!H34) -> 11B/It | I34: =IF('Week A - Template'!I34="","",'Week A - Template'!I34) -> 7B/Cs
B36: 46268 | C36: Registration
C37: Period 1 | D37: =IF('Week A - Template'!D37="","",'Week A - Template'!D37) -> 9E/It | E37: =IF('Week A - Template'!E37="","",'Week A - Template'!E37) -> - | F37: =IF('Week A - Template'!F37="","",'Week A - Template'!F37) -> 8C/Bs | G37: =IF('Week A - Template'!G37="","",'Week A - Template'!G37) -> 10E/Cs | H37: =IF('Week A - Template'!H37="","",'Week A - Template'!H37) -> 7A/Cs | I37: =IF('Week A - Template'!I37="","",'Week A - Template'!I37) -> 9F/It
C38: Period 2 | D38: =IF('Week A - Template'!D38="","",'Week A - Template'!D38) -> 10E/Cs | E38: =IF('Week A - Template'!E38="","",'Week A - Template'!E38) -> 7A/Cs | F38: =IF('Week A - Template'!F38="","",'Week A - Template'!F38) | G38: =IF('Week A - Template'!G38="","",'Week A - Template'!G38) -> 12/Cs1 | H38: =IF('Week A - Template'!H38="","",'Week A - Template'!H38) -> 8D/It | I38: =IF('Week A - Template'!I38="","",'Week A - Template'!I38) -> 11B/It
C39: Break 1
C40: Period 3 | D40: =IF('Week A - Template'!D40="","",'Week A - Template'!D40) -> 12/Cs1 | E40: =IF('Week A - Template'!E40="","",'Week A - Template'!E40) -> 8D/It | F40: =IF('Week A - Template'!F40="","",'Week A - Template'!F40) -> 11B/It | G40: =IF('Week A - Template'!G40="","",'Week A - Template'!G40) | H40: =IF('Week A - Template'!H40="","",'Week A - Template'!H40) -> 10D/Bs | I40: =IF('Week A - Template'!I40="","",'Week A - Template'!I40) -> 13/It2
C41: Period 4 | D41: =IF('Week A - Template'!D41="","",'Week A - Template'!D41) -> 7B/Cs | E41: =IF('Week A - Template'!E41="","",'Week A - Template'!E41) -> 10D/Bs | F41: =IF('Week A - Template'!F41="","",'Week A - Template'!F41) -> 13/It2 | G41: =IF('Week A - Template'!G41="","",'Week A - Template'!G41) -> 9E/It | H41: =IF('Week A - Template'!H41="","",'Week A - Template'!H41) | I41: =IF('Week A - Template'!I41="","",'Week A - Template'!I41) -> 8C/Bs
C42: Break 2
C43: Period 5 | D43: =IF('Week A - Template'!D43="","",'Week A - Template'!D43) | E43: =IF('Week A - Template'!E43="","",'Week A - Template'!E43) -> 11C/Bs | F43: =IF('Week A - Template'!F43="","",'Week A - Template'!F43) -> 8C/Bs | G43: =IF('Week A - Template'!G43="","",'Week A - Template'!G43) -> 10E/Cs | H43: =IF('Week A - Template'!H43="","",'Week A - Template'!H43) -> 7A/Cs | I43: =IF('Week A - Template'!I43="","",'Week A - Template'!I43)
C44: Period 6 | D44: =IF('Week A - Template'!D44="","",'Week A - Template'!D44) -> 10E/Cs | E44: =IF('Week A - Template'!E44="","",'Week A - Template'!E44) | F44: =IF('Week A - Template'!F44="","",'Week A - Template'!F44) -> 9F/It | G44: =IF('Week A - Template'!G44="","",'Week A - Template'!G44) -> 12/Cs1 | H44: =IF('Week A - Template'!H44="","",'Week A - Template'!H44) -> 8D/It | I44: =IF('Week A - Template'!I44="","",'Week A - Template'!I44) -> 11B/It
...

Sheet (B) September 7th - 11th
B1: WEEK B | D1: N21 | E1: N22 | F1: N23 | G1: N24 | H1: N25 | I1: N26
C2: Teacher | D2: J Barnes | E2: A Okafor | F2: - | G2: S Whitfield | H2: M Devlin | I2: —
C3: No of PCs | D3: 30 | E3: 28 | F3: 15 | G3: 32 | H3: 24 | I3: 12
C4: Telephone | D4: 2101 | E4: 2102 | F4: 0x10 | G4: 2104 | H4: 2105 | I4: 2106
B6: 46272 | C6: Registration
C7: Period 1 | D7: =IF('Week B - Template'!D7="","",'Week B - Template'!D7) -> 11B/It | E7: =IF('Week B - Template'!E7="","",'Week B - Template'!E7) -> 7B/Cs | F7: =IF('Week B - Template'!F7="","",'Week B - Template'!F7) -> 10D/Bs | G7: =IF('Week B - Template'!G7="","",'Week B - Template'!G7) | H7: =IF('Week B - Template'!H7="","",'Week B - Template'!H7) -> 9E/It | I7: =IF('Week B - Template'!I7="","",'Week B - Template'!I7) -> 11C/Bs
C8: Period 2 | D8: =IF('Week B - Template'!D8="","",'Week B - Template'!D8) -> 13/It2 | E8: =IF('Week B - Template'!E8="","",'Week B - Template'!E8) -> 9E/It | F8: =IF('Week B - Template'!F8="","",'Week B - Template'!F8) -> 11C/Bs | G8: =IF('Week B - Template'!G8="","",'Week B - Template'!G8) -> 8C/Bs | H8: =IF('Week B - Template'!H8="","",'Week B - Template'!H8) | I8: =IF('Week B - Template'!I8="","",'Week B - Template'!I8) -> 7A/Cs
C9: Break 1
C10: Period 3 | D10: =IF('Week B - Template'!D10="","",'Week B - Template'!D10) | E10: =IF('Week B - Template'!E10="","",'Week B - Template'!E10) -> 10E/Cs | F10: =IF('Week B - Template'!F10="","",'Week B - Template'!F10) -> 7A/Cs | G10: =IF('Week B - Template'!G10="","",'Week B - Template'!G10) -> 9F/It | H10: =IF('Week B - Template'!H10="","",'Week B - Template'!H10) -> 12/Cs1 | I10: =IF('Week B - Template'!I10="","",'Week B - Template'!I10)
C11: Period 4 | D11: =IF('Week B - Template'!D11="","",'Week B - Template'!D11) -> 9F/It | E11: =IF('Week B - Template'!E11="","",'Week B - Template'!E11) | F11: =IF('Week B - Template'!F11="","",'Week B - Template'!F11) -> 8D/It | G11: =IF('Week B - Template'!G11="","",'Week B - Template'!G11) -> 11B/It | H11: =IF('Week B - Template'!H11="","",'Week B - Template'!H11) -> 7B/Cs | I11: =IF('Week B - Template'!I11="","",'Week B - Template'!I11) -> 10D/Bs
C12: Break 2
C13: Period 5 | D13: =IF('Week B - Template'!D13="","",'Week B - Template'!D13) -> 11B/It | E13: =IF('Week B - Template'!E13="","",'Week B - Template'!E13) -> 7B/Cs | F13: =IF('Week B - Template'!F13="","",'Week B - Template'!F13) | G13: =IF('Week B - Template'!G13="","",'Week B - Template'!G13) -> 13/It2 | H13: =IF('Week B - Template'!H13="","",'Week B - Template'!H13) -> 9E/It | I13: =IF('Week B - Template'!I13="","",'Week B - Template'!I13) -> 11C/Bs
C14: Period 6 | D14: =IF('Week B - Template'!D14="","",'Week B - Template'!D14) -> 13/It2 | E14: =IF('Week B - Template'!E14="","",'Week B - Template'!E14) -> 9E/It | F14: =IF('Week B - Template'!F14="","",'Week B - Template'!F14) -> 11C/Bs | G14: =IF('Week B - Template'!G14="","",'Week B - Template'!G14) | H14: =IF('Week B - Template'!H14="","",'Week B - Template'!H14) -> 10E/Cs | I14: =IF('Week B - Template'!I14="","",'Week B - Template'!I14) -> 7A/Cs
B16: 46273 | C16: Registration
C17: Period 1 | D17: =IF('Week B - Template'!D17="","",'Week B - Template'!D17) -> 8D/It | E17: =IF('Week B - Template'!E17="","",'Week B - Template'!E17) -> 11B/It | F17: =IF('Week B - Template'!F17="","",'Week B - Template'!F17) | G17: =IF('Week B - Template'!G17="","",'Week B - Template'!G17) -> 10D/Bs | H17: =IF('Week B - Template'!H17="","",'Week B - Template'!H17) -> 13/It2 | I17: =IF('Week B - Template'!I17="","",'Week B - Template'!I17) -> 9E/It
C18: Period 2 | D18: =IF('Week B - Template'!D18="","",'Week B - Template'!D18) -> 10D/Bs | E18: =IF('Week B - Template'!E18="","",'Week B - Template'!E18) -> 13/It2 | F18: =IF('Week B - Template'!F18="","",'Week B - Template'!F18) -> 9E/It | G18: =IF('Week B - Template'!G18="","",'Week B - Template'!G18) | H18: =IF('Week B - Template'!H18="","",'Week B - Template'!H18) -> 8C/Bs | I18: =IF('Week B - Template'!I18="","",'Week B - Template'!I18) -> 10E/Cs
C19: Break 1
C20: Period 3 | D20: =IF('Week B - Template'!D20="","",'Week B - Template'!D20) -> 11C/Bs | E20: =IF('Week B - Template'!E20="","",'Week B - Template'!E20) -> 8C/Bs | F20: =IF('Week B - Template'!F20="","",'Week B - Template'!F20) -> 10E/Cs | G20: =IF('Week B - Template'!G20="","",'Week B - Template'!G20) -> 7A/Cs | H20: =IF('Week B - Template'!H20="","",'Week B - Template'!H20) | I20: =IF('Week B - Template'!I20="","",'Week B - Template'!I20) -> 12/Cs1
C21: Period 4 | D21: =IF('Week B - Template'!D21="","",'Week B - Template'!D21) | E21: =IF('Week B - Template'!E21="","",'Week B - Template'!E21) -> 9F/It | F21: =IF('Week B - Template'!F21="","",'Week B - Template'!F21) -> 12/Cs1 | G21: =IF('Week B - Template'!G21="","",'Week B - Template'!G21) -> 8D/It | H21: =IF('Week B - Template'!H21="","",'Week B - Template'!H21) -> 11B/It | I21: =IF('Week B - Template'!I21="","",'Week B - Template'!I21)
C22: Break 2
C23: Period 5 | D23: =IF('Week B - Template'!D23="","",'Week B - Template'!D23) -> 8D/It | E23: =IF('Week B - Template'!E23="","",'Week B - Template'!E23) | F23: =IF('Week B - Template'!F23="","",'Week B - Template'!F23) -> 7B/Cs | G23: =IF('Week B - Template'!G23="","",'Week B - Template'!G23) -> 10D/Bs | H23: =IF('Week B - Template'!H23="","",'Week B - Template'!H23) -> 13/It2 | I23: =IF('Week B - Template'!I23="","",'Week B - Template'!I23) -> 9E/It
C24: Period 6 | D24: =IF('Week B - Template'!D24="","",'Week B - Template'!D24) -> 10D/Bs | E24: =IF('Week B - Template'!E24="","",'Week B - Template'!E24) -> 13/It2 | F24: =IF('Week B - Template'!F24="","",'Week B - Template'!F24) | G24: =IF('Week B - Template'!G24="","",'Week B - Template'!G24) -> 11C/Bs | H24: =IF('Week B - Template'!H24="","",'Week B - Template'!H24) -> 8C/Bs | I24: =IF('Week B - Template'!I24="","",'Week B - Template'!I24) -> 10E/Cs
B26: 46274 | C26: Registration
C27: Period 1 | D27: =IF('Week B - Template'!D27="","",'Week B - Template'!D27) -> 12/Cs1 | E27: =IF('Week B - Template'!E27="","",'Week B - Template'!E27) | F27: =IF('Week B - Template'!F27="","",'Week B - Template'!F27) -> 11B/It | G27: =IF('Week B - Template'!G27="","",'Week B - Template'!G27) -> 7B/Cs | H27: =IF('Week B - Template'!H27="","",'Week B - Template'!H27) -> 10D/Bs | I27: =IF('Week B - Template'!I27="","",'Week B - Template'!I27) -> 13/It2
C28: Period 2 | D28: =IF('Week B - Template'!D28="","",'Week B - Template'!D28) -> 7B/Cs | E28: =IF('Week B - Template'!E28="","",'Week B - Template'!E28) -> 10D/Bs | F28: =IF('Week B - Template'!F28="","",'Week B - Template'!F28) | G28: =IF('Week B - Template'!G28="","",'Week B - Template'!G28) -> 9E/It | H28: =IF('Week B - Template'!H28="","",'Week B - Template'!H28) -> 11C/Bs | I28: =IF('Week B - Template'!I28="","",'Week B - Template'!I28) -> 8C/Bs
C29: Break 1
C30: Period 3 | D30: =IF('Week B - Template'!D30="","",'Week B - Template'!D30) -> 9E/It | E30: =IF('Week B - Template'!E30="","",'Week B - Template'!E30) -> 11C/Bs | F30: =IF('Week B - Template'!F30="","",'Week B - Template'!F30) -> 8C/Bs | G30: =IF('Week B - Template'!G30="","",'Week B - Template'!G30) | H30: =IF('Week B - Template'!H30="","",'Week B - Template'!H30) -> 7A/Cs | I30: =IF('Week B - Template'!I30="","",'Week B - Template'!I30) -> 9F/It
C31: Period 4 | D31: =IF('Week B - Template'!D31="","",'Week B - Template'!D31) -> 10E/Cs | E31: =IF('Week B - Template'!E31="","",'Week B - Template'!E31) -> 7A/Cs | F31: =IF('Week B - Template'!F31="","",'Week B - Template'!F31) -> 9F/It | G31: =IF('Week B - Template'!G31="","",'Week B - Template'!G31) -> 12/Cs1 | H31: =IF('Week B - Template'!H31="","",'Week B - Template'!H31) | I31: =IF('Week B - Template'!I31="","",'Week B - Template'!I31) -> 11B/It
C32: Break 2
C33: Period 5 | D33: =IF('Week B - Template'!D33="","",'Week B - Template'!D33) | E33: =IF('Week B - Template'!E33="","",'Week B - Template'!E33) -> 8D/It | F33: =IF('Week B - Template'!F33="","",'Week B - Template'!F33) -> 11B/It | G33: =IF('Week B - Template'!G33="","",'Week B - Template'!G33) -> 7B/Cs | H33: =IF('Week B - Template'!H33="","",'Week B - Template'!H33) -> 10D/Bs | I33: =IF('Week B - Template'!I33="","",'Week B - Template'!I33)
C34: Period 6 | D34: =IF('Week B - Template'!D34="","",'Week B - Template'!D34) -> 7B/Cs | E34: =IF('Week B - Template'!E34="","",'Week B - Template'!E34) | F34: =IF('Week B - Template'!F34="","",'Week B - Template'!F34) -> 13/It2 | G34: =IF('Week B - Template'!G34="","",'Week B - Template'!G34) -> 9E/It | H34: =IF('Week B - Template'!H34="","",'Week B - Template'!H34) -> 11C/Bs | I34: =IF('Week B - Template'!I34="","",'Week B - Template'!I34) -> 8C/Bs
B36: 46275 | C36: Registration
C37: Period 1 | D37: =IF('Week B - Template'!D37="","",'Week B - Template'!D37) | E37: =IF('Week B - Template'!E37="","",'Week B - Template'!E37) -> 12/Cs1 | F37: =IF('Week B - Template'!F37="","",'Week B - Template'!F37) -> 8D/It | G37: =IF('Week B - Template'!G37="","",'Week B - Template'!G37) -> 11B/It | H37: =IF('Week B - Template'!H37="","",'Week B - Template'!H37) -> 7B/Cs | I37: =IF('Week B - Template'!I37="","",'Week B - Template'!I37)
C38: Period 2 | D38: =IF('Week B - Template'!D38="","",'Week B - Template'!D38) -> 11B/It | E38: =IF('Week B - Template'!E38="","",'Week B - Template'!E38) | F38: =IF('Week B - Template'!F38="","",'Week B - Template'!F38) -> 10D/Bs | G38: =IF('Week B - Template'!G38="","",'Week B - Template'!G38) -> 13/It2 | H38: =IF('Week B - Template'!H38="","",'Week B - Template'!H38) -> 9E/It | I38: =IF('Week B - Template'!I38="","",'Week B - Template'!I38) -> 11C/Bs
C39: Break 1
C40: Period 3 | D40: =IF('Week B - Template'!D40="","",'Week B - Template'!D40) -> 13/It2 | E40: =IF('Week B - Template'!E40="","",'Week B - Template'!E40) -> 9E/It | F40: =IF('Week B - Template'!F40="","",'Week B - Template'!F40) | G40: =IF('Week B - Template'!G40="","",'Week B - Template'!G40) -> 8C/Bs | H40: =IF('Week B - Template'!H40="","",'Week B - Template'!H40) -> 10E/Cs | I40: =IF('Week B - Template'!I40="","",'Week B - Template'!I40) -> 7A/Cs
C41: Period 4 | D41: =IF('Week B - Template'!D41="","",'Week B - Template'!D41) -> 8C/Bs | E41: =IF('Week B - Template'!E41="","",'Week B - Template'!E41) -> 10E/Cs | F41: =IF('Week B - Template'!F41="","",'Week B - Template'!F41) -> 7A/Cs | G41: =IF('Week B - Template'!G41="","",'Week B - Template'!G41) | H41: =IF('Week B - Template'!H41="","",'Week B - Template'!H41) -> 12/Cs1 | I41: =IF('Week B - Template'!I41="","",'Week B - Template'!I41) -> 8D/It
C42: Break 2
C43: Period 5 | D43: =IF('Week B - Template'!D43="","",'Week B - Template'!D43) -> 9F/It | E43: =IF('Week B - Template'!E43="","",'Week B - Template'!E43) -> 12/Cs1 | F43: =IF('Week B - Template'!F43="","",'Week B - Template'!F43) -> 8D/It | G43: =IF('Week B - Template'!G43="","",'Week B - Template'!G43) -> 11B/It | H43: =IF('Week B - Template'!H43="","",'Week B - Template'!H43) | I43: =IF('Week B - Template'!I43="","",'Week B - Template'!I43) -> 10D/Bs
C44: Period 6 | D44: =IF('Week B - Template'!D44="","",'Week B - Template'!D44) | E44: =IF('Week B - Template'!E44="","",'Week B - Template'!E44) -> 7B/Cs | F44: =IF('Week B - Template'!F44="","",'Week B - Template'!F44) -> 10D/Bs | G44: =IF('Week B - Template'!G44="","",'Week B - Template'!G44) -> 13/It2 | H44: =IF('Week B - Template'!H44="","",'Week B - Template'!H44) -> 9E/It | I44: =IF('Week B - Template'!I44="","",'Week B - Template'!I44)
...

Sheet (A) September 14th - 18th
B1: WEEK A | D1: N21 | E1: N22 | F1: N23 | G1: N24 | H1: N25 | I1: N26
C2: Teacher | D2: J Barnes | E2: A Okafor | F2: - | G2: S Whitfield | H2: M Devlin | I2: —
C3: No of PCs | D3: 30 | E3: 28 | F3: 15 | G3: 32 | H3: 24 | I3: 12
C4: Telephone | D4: 2101 | E4: 2102 | F4: 0x10 | G4: 2104 | H4: 2105 | I4: 2106
B6: 46279 | C6: Registration
C7: Period 1 | D7: =IF('Week A - Template'!D7="","",'Week A - Template'!D7) -> 10E/Cs | E7: =IF('Week A - Template'!E7="","",'Week A - Template'!E7) -> 7A/Cs | F7: =IF('Week A - Template'!F7="","",'Week A - Template'!F7) -> 9F/It | G7: =IF('Week A - Template'!G7="","",'Week A - Template'!G7) -> 12/Cs1 | H7: =IF('Week A - Template'!H7="","",'Week A - Template'!H7) | I7: =IF('Week A - Template'!I7="","",'Week A - Template'!I7) -> 11B/It
C8: Period 2 | D8: =IF('Week A - Template'!D8="","",'Week A - Template'!D8) | E8: =IF('Week A - Template'!E8="","",'Week A - Template'!E8) -> 8D/It | F8: =IF('Week A - Template'!F8="","",'Week A - Template'!F8) -> 11B/It | G8: =IF('Week A - Template'!G8="","",'Week A - Template'!G8) -> 7B/Cs | H8: =IF('Week A - Template'!H8="","",'Week A - Template'!H8) -> 10D/Bs | I8: =IF('Week A - Template'!I8="","",'Week A - Template'!I8)
C9: Break 1
C10: Period 3 | D10: =IF('Week A - Template'!D10="","",'Week A - Template'!D10) -> 7B/Cs | E10: =IF('Week A - Template'!E10="","",'Week A - Template'!E10) | F10: =IF('Week A - Template'!F10="","",'Week A - Template'!F10) -> 13/It2 | G10: =IF('Week A - Template'!G10="","",'Week A - Template'!G10) -> 9E/It | H10: =IF('Week A - Template'!H10="","",'Week A - Template'!H10) -> 11C/Bs | I10: =IF('Week A - Template'!I10="","",'Week A - Template'!I10) -> 8C/Bs
C11: Period 4 | D11: =IF('Week A - Template'!D11="","",'Week A - Template'!D11) -> 9E/It | E11: =IF('Week A - Template'!E11="","",'Week A - Template'!E11) -> 11C/Bs | F11: =IF('Week A - Template'!F11="","",'Week A - Template'!F11) | G11: =IF('Week A - Template'!G11="","",'Week A - Template'!G11) -> 10E/Cs | H11: =IF('Week A - Template'!H11="","",'Week A - Template'!H11) -> 7A/Cs | I11: =IF('Week A - Template'!I11="","",'Week A - Template'!I11) -> 9F/It
C12: Break 2
C13: Period 5 | D13: =IF('Week A - Template'!D13="","",'Week A - Template'!D13) -> 10E/Cs | E13: =IF('Week A - Template'!E13="","",'Week A - Template'!E13) -> 7A/Cs | F13: =IF('Week A - Template'!F13="","",'Week A - Template'!F13) -> 9F/It | G13: =IF('Week A - Template'!G13="","",'Week A - Template'!G13) | H13: =IF('Week A - Template'!H13="","",'Week A - Template'!H13) -> 8D/It | I13: =IF('Week A - Template'!I13="","",'Week A - Template'!I13) -> 11B/It
C14: Period 6 | D14: =IF('Week A - Template'!D14="","",'Week A - Template'!D14) -> 12/Cs1 | E14: =IF('Week A - Template'!E14="","",'Week A - Template'!E14) -> 8D/It | F14: =IF('Week A - Template'!F14="","",'Week A - Template'!F14) -> 11B/It | G14: =IF('Week A - Template'!G14="","",'Week A - Template'!G14) -> 7B/Cs | H14: =IF('Week A - Template'!H14="","",'Week A - Template'!H14) | I14: =IF('Week A - Template'!I14="","",'Week A - Template'!I14) -> 13/It2
B16: 46280 | C16: Registration
C17: Period 1 | D17: =IF('Week A - Template'!D17="","",'Week A - Template'!D17) -> 8C/Bs | E17: =IF('Week A - Template'!E17="","",'Week A - Template'!E17) -> 10E/Cs | F17: =IF('Week A - Template'!F17="","",'Week A - Template'!F17) -> 7A/Cs | G17: =IF('Week A - Template'!G17="","",'Week A - Template'!G17) | H17: =IF('Week A - Template'!H17="","",'Week A - Template'!H17) -> 12/Cs1 | I17: =IF('Week A - Template'!I17="","",'Week A - Template'!I17) -> 8D/It
C18: Period 2 | D18: =IF('Week A - Template'!D18="","",'Week A - Template'!D18) -> 9F/It | E18: =IF('Week A - Template'!E18="","",'Week A - Template'!E18) -> 12/Cs1 | F18: =IF('Week A - Template'!F18="","",'Week A - Template'!F18) -> 8D/It | G18: =IF('Week A - Template'!G18="","",'Week A - Template'!G18) -> 11B/It | H18: =IF('Week A - Template'!H18="","",'Week A - Template'!H18) | I18: =IF('Week A - Template'!I18="","",'Week A - Template'!I18) -> 10D/Bs
C19: Break 1
C20: Period 3 | D20: =IF('Week A - Template'!D20="","",'Week A - Template'!D20) | E20: =IF('Week A - Template'!E20="","",'Week A - Template'!E20) -> 7B/Cs | F20: =IF('Week A - Template'!F20="","",'Week A - Template'!F20) -> 10D/Bs | G20: =IF('Week A - Template'!G20="","",'Week A - Template'!G20) -> 13/It2 | H20: =IF('Week A - Template'!H20="","",'Week A - Template'!H20) -> 9E/It | I20: =IF('Week A - Template'!I20="","",'Week A - Template'!I20)
C21: Period 4 | D21: =IF('Week A - Template'!D21="","",'Week A - Template'!D21) -> 13/It2 | E21: =IF('Week A - Template'!E21="","",'Week A - Template'!E21) | F21: =IF('Week A - Template'!F21="","",'Week A - Template'!F21) -> 11C/Bs | G21: =IF('Week A - Template'!G21="","",'Week A - Template'!G21) -> 8C/Bs | H21: =IF('Week A - Template'!H21="","",'Week A - Template'!H21) -> 10E/Cs | I21: =IF('Week A - Template'!I21="","",'Week A - Template'!I21) -> 7A/Cs
C22: Break 2
C23: Period 5 | D23: =IF('Week A - Template'!D23="","",'Week A - Template'!D23) -> 8C/Bs | E23: =IF('Week A - Template'!E23="","",'Week A - Template'!E23) -> 10E/Cs | F23: =IF('Week A - Template'!F23="","",'Week A - Template'!F23) | G23: =IF('Week A - Template'!G23="","",'Week A - Template'!G23) -> 9F/It | H23: =IF('Week A - Template'!H23="","",'Week A - Template'!H23) -> 12/Cs1 | I23: =IF('Week A - Template'!I23="","",'Week A - Template'!I23) -> 8D/It
C24: Period 6 | D24: =IF('Week A - Template'!D24="","",'Week A - Template'!D24) -> 9F/It | E24: =IF('Week A - Template'!E24="","",'Week A - Template'!E24) -> 12/Cs1 | F24: =IF('Week A - Template'!F24="","",'Week A - Template'!F24) -> 8D/It | G24: =IF('Week A - Template'!G24="","",'Week A - Template'!G24) | H24: =IF('Week A - Template'!H24="","",'Week A - Template'!H24) -> 7B/Cs | I24: =IF('Week A - Template'!I24="","",'Week A - Template'!I24) -> 10D/Bs
B26: 46281 | C26: Registration
C27: Period 1 | D27: =IF('Week A - Template'!D27="","",'Week A - Template'!D27) -> 11C/Bs | E27: =IF('Week A - Template'!E27="","",'Week A - Template'!E27) -> 8C/Bs | F27: =IF('Week A - Template'!F27="","",'Week A - Template'!F27) | G27: =IF('Week A - Template'!G27="","",'Week A - Template'!G27) -> 7A/Cs | H27: =IF('Week A - Template'!H27="","",'Week A - Template'!H27) -> 9F/It | I27: =IF('Week A - Template'!I27="","",'Week A - Template'!I27) -> 12/Cs1
C28: Period 2 | D28: =IF('Week A - Template'!D28="","",'Week A - Template'!D28) -> 7A/Cs | E28: =IF('Week A - Template'!E28="","",'Week A - Template'!E28) -> 9F/It | F28: =IF('Week A - Template'!F28="","",'Week A - Template'!F28) -> 12/Cs1 | G28: =IF('Week A - Template'!G28="","",'Week A - Template'!G28) | H28: =IF('Week A - Template'!H28="","",'Week A - Template'!H28) -> 11B/It | I28: =IF('Week A - Template'!I28="","",'Week A - Template'!I28) -> 7B/Cs
C29: Break 1
C30: Period 3 | D30: =IF('Week A - Template'!D30="","",'Week A - Template'!D30) -> 8D/It | E30: =IF('Week A - Template'!E30="","",'Week A - Template'!E30) -> 11B/It | F30: =IF('Week A - Template'!F30="","",'Week A - Template'!F30) -> 7B/Cs | G30: =IF('Week A - Template'!G30="","",'Week A - Template'!G30) -> 10D/Bs | H30: =IF('Week A - Template'!H30="","",'Week A - Template'!H30) | I30: =IF('Week A - Template'!I30="","",'Week A - Template'!I30) -> 9E/It
C31: Period 4 | D31: =IF('Week A - Template'!D31="","",'Week A - Template'!D31) | E31: =IF('Week A - Template'!E31="","",'Week A - Template'!E31) -> 13/It2 | F31: =IF('Week A - Template'!F31="","",'Week A - Template'!F31) -> 9E/It | G31: =IF('Week A - Template'!G31="","",'Week A - Template'!G31) -> 11C/Bs | H31: =IF('Week A - Template'!H31="","",'Week A - Template'!H31) -> 8C/Bs | I31: =IF('Week A - Template'!I31="","",'Week A - Template'!I31)
C32: Break 2
C33: Period 5 | D33: =IF('Week A - Template'!D33="","",'Week A - Template'!D33) -> 11C/Bs | E33: =IF('Week A - Template'!E33="","",'Week A - Template'!E33) | F33: =IF('Week A - Template'!F33="","",'Week A - Template'!F33) -> 10E/Cs | G33: =IF('Week A - Template'!G33="","",'Week A - Template'!G33) -> 7A/Cs | H33: =IF('Week A - Template'!H33="","",'Week A - Template'!H33) -> 9F/It | I33: =IF('Week A - Template'!I33="","",'Week A - Template'!I33) -> 12/Cs1
C34: Period 6 | D34: =IF('Week A - Template'!D34="","",'Week A - Template'!D34) -> 7A/Cs | E34: =IF('Week A - Template'!E34="","",'Week A - Template'!E34) -> 9F/It | F34: =IF('Week A - Template'!F34="","",'Week A - Template'!F34) | G34: =IF('Week A - Template'!G34="","",'Week A - Template'!G34) -> 8D/It | H34: =IF('Week A - Template'!H34="","",'Week A - Template'!H34) -> 11B/It | I34: =IF('Week A - Template'!I34="","",'Week A - Template'!I34) -> 7B/Cs
B36: 46282 | C36: Registration
C37: Period 1 | D37: =IF('Week A - Template'!D37="","",'Week A - Template'!D37) -> 9E/It | E37: =IF('Week A - Template'!E37="","",'Week A - Template'!E37) -> - | F37: =IF('Week A - Template'!F37="","",'Week A - Template'!F37) -> 8C/Bs | G37: =IF('Week A - Template'!G37="","",'Week A - Template'!G37) -> 10E/Cs | H37: =IF('Week A - Template'!H37="","",'Week A - Template'!H37) -> 7A/Cs | I37: =IF('Week A - Template'!I37="","",'Week A - Template'!I37) -> 9F/It
C38: Period 2 | D38: =IF('Week A - Template'!D38="","",'Week A - Template'!D38) -> 10E/Cs | E38: =IF('Week A - Template'!E38="","",'Week A - Template'!E38) -> 7A/Cs | F38: =IF('Week A - Template'!F38="","",'Week A - Template'!F38) | G38: =IF('Week A - Template'!G38="","",'Week A - Template'!G38) -> 12/Cs1 | H38: =IF('Week A - Template'!H38="","",'Week A - Template'!H38) -> 8D/It | I38: =IF('Week A - Template'!I38="","",'Week A - Template'!I38) -> 11B/It
C39: Break 1
C40: Period 3 | D40: =IF('Week A - Template'!D40="","",'Week A - Template'!D40) -> 12/Cs1 | E40: =IF('Week A - Template'!E40="","",'Week A - Template'!E40) -> 8D/It | F40: =IF('Week A - Template'!F40="","",'Week A - Template'!F40) -> 11B/It | G40: =IF('Week A - Template'!G40="","",'Week A - Template'!G40) | H40: =IF('Week A - Template'!H40="","",'Week A - Template'!H40) -> 10D/Bs | I40: =IF('Week A - Template'!I40="","",'Week A - Template'!I40) -> 13/It2
C41: Period 4 | D41: =IF('Week A - Template'!D41="","",'Week A - Template'!D41) -> 7B/Cs | E41: =IF('Week A - Template'!E41="","",'Week A - Template'!E41) -> 10D/Bs | F41: =IF('Week A - Template'!F41="","",'Week A - Template'!F41) -> 13/It2 | G41: =IF('Week A - Template'!G41="","",'Week A - Template'!G41) -> 9E/It | H41: =IF('Week A - Template'!H41="","",'Week A - Template'!H41) | I41: =IF('Week A - Template'!I41="","",'Week A - Template'!I41) -> 8C/Bs
C42: Break 2
C43: Period 5 | D43: =IF('Week A - Template'!D43="","",'Week A - Template'!D43) | E43: =IF('Week A - Template'!E43="","",'Week A - Template'!E43) -> 11C/Bs | F43: =IF('Week A - Template'!F43="","",'Week A - Template'!F43) -> 8C/Bs | G43: =IF('Week A - Template'!G43="","",'Week A - Template'!G43) -> 10E/Cs | H43: =IF('Week A - Template'!H43="","",'Week A - Template'!H43) -> 7A/Cs | I43: =IF('Week A - Template'!I43="","",'Week A - Template'!I43)
C44: Period 6 | D44: =IF('Week A - Template'!D44="","",'Week A - Template'!D44) -> 10E/Cs | E44: =IF('Week A - Template'!E44="","",'Week A - Template'!E44) | F44: =IF('Week A - Template'!F44="","",'Week A - Template'!F44) -> 9F/It | G44: =IF('Week A - Template'!G44="","",'Week A - Template'!G44) -> 12/Cs1 | H44: =IF('Week A - Template'!H44="","",'Week A - Template'!H44) -> 8D/It | I44: =IF('Week A - Template'!I44="","",'Week A - Template'!I44) -> 11B/It
...

Sheet (B) September 21st - 25th
B1: WEEK B | D1: N21 | E1: N22 | F1: N23 | G1: N24 | H1: N25 | I1: N26
C2: Teacher | D2: J Barnes | E2: A Okafor | F2: - | G2: S Whitfield | H2: M Devlin | I2: —
C3: No of PCs | D3: 30 | E3: 28 | F3: 15 | G3: 32 | H3: 24 | I3: 12
C4: Telephone | D4: 2101 | E4: 2102 | F4: 0x10 | G4: 2104 | H4: 2105 | I4: 2106
B6: 46286 | C6: Registration
C7: Period 1 | D7: =IF('Week B - Template'!D7="","",'Week B - Template'!D7) -> 11B/It | E7: =IF('Week B - Template'!E7="","",'Week B - Template'!E7) -> 7B/Cs | F7: =IF('Week B - Template'!F7="","",'Week B - Template'!F7) -> 10D/Bs | G7: =IF('Week B - Template'!G7="","",'Week B - Template'!G7) | H7: =IF('Week B - Template'!H7="","",'Week B - Template'!H7) -> 9E/It | I7: =IF('Week B - Template'!I7="","",'Week B - Template'!I7) -> 11C/Bs
C8: Period 2 | D8: =IF('Week B - Template'!D8="","",'Week B - Template'!D8) -> 13/It2 | E8: =IF('Week B - Template'!E8="","",'Week B - Template'!E8) -> 9E/It | F8: =IF('Week B - Template'!F8="","",'Week B - Template'!F8) -> 11C/Bs | G8: =IF('Week B - Template'!G8="","",'Week B - Template'!G8) -> 8C/Bs | H8: =IF('Week B - Template'!H8="","",'Week B - Template'!H8) | I8: =IF('Week B - Template'!I8="","",'Week B - Template'!I8) -> 7A/Cs
C9: Break 1
C10: Period 3 | D10: =IF('Week B - Template'!D10="","",'Week B - Template'!D10) | E10: =IF('Week B - Template'!E10="","",'Week B - Template'!E10) -> 10E/Cs | F10: =IF('Week B - Template'!F10="","",'Week B - Template'!F10) -> 7A/Cs | G10: =IF('Week B - Template'!G10="","",'Week B - Template'!G10) -> 9F/It | H10: =IF('Week B - Template'!H10="","",'Week B - Template'!H10) -> 12/Cs1 | I10: =IF('Week B - Template'!I10="","",'Week B - Template'!I10)
C11: Period 4 | D11: =IF('Week B - Template'!D11="","",'Week B - Template'!D11) -> 9F/It | E11: =IF('Week B - Template'!E11="","",'Week B - Template'!E11) | F11: =IF('Week B - Template'!F11="","",'Week B - Template'!F11) -> 8D/It | G11: =IF('Week B - Template'!G11="","",'Week B - Template'!G11) -> 11B/It | H11: =IF('Week B - Template'!H11="","",'Week B - Template'!H11) -> 7B/Cs | I11: =IF('Week B - Template'!I11="","",'Week B - Template'!I11) -> 10D/Bs
C12: Break 2
C13: Period 5 | D13: =IF('Week B - Template'!D13="","",'Week B - Template'!D13) -> 11B/It | E13: =IF('Week B - Template'!E13="","",'Week B - Template'!E13) -> 7B/Cs | F13: =IF('Week B - Template'!F13="","",'Week B - Template'!F13) | G13: =IF('Week B - Template'!G13="","",'Week B - Template'!G13) -> 13/It2 | H13: =IF('Week B - Template'!H13="","",'Week B - Template'!H13) -> 9E/It | I13: =IF('Week B - Template'!I13="","",'Week B - Template'!I13) -> 11C/Bs
C14: Period 6 | D14: =IF('Week B - Template'!D14="","",'Week B - Template'!D14) -> 13/It2 | E14: =IF('Week B - Template'!E14="","",'Week B - Template'!E14) -> 9E/It | F14: =IF('Week B - Template'!F14="","",'Week B - Template'!F14) -> 11C/Bs | G14: =IF('Week B - Template'!G14="","",'Week B - Template'!G14) | H14: =IF('Week B - Template'!H14="","",'Week B - Template'!H14) -> 10E/Cs | I14: =IF('Week B - Template'!I14="","",'Week B - Template'!I14) -> 7A/Cs
B16: 46287 | C16: Registration
C17: Period 1 | D17: =IF('Week B - Template'!D17="","",'Week B - Template'!D17) -> 8D/It | E17: =IF('Week B - Template'!E17="","",'Week B - Template'!E17) -> 11B/It | F17: =IF('Week B - Template'!F17="","",'Week B - Template'!F17) | G17: =IF('Week B - Template'!G17="","",'Week B - Template'!G17) -> 10D/Bs | H17: =IF('Week B - Template'!H17="","",'Week B - Template'!H17) -> 13/It2 | I17: =IF('Week B - Template'!I17="","",'Week B - Template'!I17) -> 9E/It
C18: Period 2 | D18: =IF('Week B - Template'!D18="","",'Week B - Template'!D18) -> 10D/Bs | E18: =IF('Week B - Template'!E18="","",'Week B - Template'!E18) -> 13/It2 | F18: =IF('Week B - Template'!F18="","",'Week B - Template'!F18) -> 9E/It | G18: =IF('Week B - Template'!G18="","",'Week B - Template'!G18) | H18: =IF('Week B - Template'!H18="","",'Week B - Template'!H18) -> 8C/Bs | I18: =IF('Week B - Template'!I18="","",'Week B - Template'!I18) -> 10E/Cs
C19: Break 1
C20: Period 3 | D20: =IF('Week B - Template'!D20="","",'Week B - Template'!D20) -> 11C/Bs | E20: =IF('Week B - Template'!E20="","",'Week B - Template'!E20) -> 8C/Bs | F20: =IF('Week B - Template'!F20="","",'Week B - Template'!F20) -> 10E/Cs | G20: =IF('Week B - Template'!G20="","",'Week B - Template'!G20) -> 7A/Cs | H20: =IF('Week B - Template'!H20="","",'Week B - Template'!H20) | I20: =IF('Week B - Template'!I20="","",'Week B - Template'!I20) -> 12/Cs1
C21: Period 4 | D21: =IF('Week B - Template'!D21="","",'Week B - Template'!D21) | E21: =IF('Week B - Template'!E21="","",'Week B - Template'!E21) -> 9F/It | F21: =IF('Week B - Template'!F21="","",'Week B - Template'!F21) -> 12/Cs1 | G21: =IF('Week B - Template'!G21="","",'Week B - Template'!G21) -> 8D/It | H21: =IF('Week B - Template'!H21="","",'Week B - Template'!H21) -> 11B/It | I21: =IF('Week B - Template'!I21="","",'Week B - Template'!I21)
C22: Break 2
C23: Period 5 | D23: =IF('Week B - Template'!D23="","",'Week B - Template'!D23) -> 8D/It | E23: =IF('Week B - Template'!E23="","",'Week B - Template'!E23) | F23: =IF('Week B - Template'!F23="","",'Week B - Template'!F23) -> 7B/Cs | G23: =IF('Week B - Template'!G23="","",'Week B - Template'!G23) -> 10D/Bs | H23: =IF('Week B - Template'!H23="","",'Week B - Template'!H23) -> 13/It2 | I23: =IF('Week B - Template'!I23="","",'Week B - Template'!I23) -> 9E/It
C24: Period 6 | D24: =IF('Week B - Template'!D24="","",'Week B - Template'!D24) -> 10D/Bs | E24: =IF('Week B - Template'!E24="","",'Week B - Template'!E24) -> 13/It2 | F24: =IF('Week B - Template'!F24="","",'Week B - Template'!F24) | G24: =IF('Week B - Template'!G24="","",'Week B - Template'!G24) -> 11C/Bs | H24: =IF('Week B - Template'!H24="","",'Week B - Template'!H24) -> 8C/Bs | I24: =IF('Week B - Template'!I24="","",'Week B - Template'!I24) -> 10E/Cs
B26: 46288 | C26: Registration
C27: Period 1 | D27: =IF('Week B - Template'!D27="","",'Week B - Template'!D27) -> 12/Cs1 | E27: =IF('Week B - Template'!E27="","",'Week B - Template'!E27) | F27: =IF('Week B - Template'!F27="","",'Week B - Template'!F27) -> 11B/It | G27: =IF('Week B - Template'!G27="","",'Week B - Template'!G27) -> 7B/Cs | H27: =IF('Week B - Template'!H27="","",'Week B - Template'!H27) -> 10D/Bs | I27: =IF('Week B - Template'!I27="","",'Week B - Template'!I27) -> 13/It2
C28: Period 2 | D28: =IF('Week B - Template'!D28="","",'Week B - Template'!D28) -> 7B/Cs | E28: =IF('Week B - Template'!E28="","",'Week B - Template'!E28) -> 10D/Bs | F28: =IF('Week B - Template'!F28="","",'Week B - Template'!F28) | G28: =IF('Week B - Template'!G28="","",'Week B - Template'!G28) -> 9E/It | H28: =IF('Week B - Template'!H28="","",'Week B - Template'!H28) -> 11C/Bs | I28: =IF('Week B - Template'!I28="","",'Week B - Template'!I28) -> 8C/Bs
C29: Break 1
C30: Period 3 | D30: =IF('Week B - Template'!D30="","",'Week B - Template'!D30) -> 9E/It | E30: =IF('Week B - Template'!E30="","",'Week B - Template'!E30) -> 11C/Bs | F30: =IF('Week B - Template'!F30="","",'Week B - Template'!F30) -> 8C/Bs | G30: =IF('Week B - Template'!G30="","",'Week B - Template'!G30) | H30: =IF('Week B - Template'!H30="","",'Week B - Template'!H30) -> 7A/Cs | I30: =IF('Week B - Template'!I30="","",'Week B - Template'!I30) -> 9F/It
C31: Period 4 | D31: =IF('Week B - Template'!D31="","",'Week B - Template'!D31) -> 10E/Cs | E31: =IF('Week B - Template'!E31="","",'Week B - Template'!E31) -> 7A/Cs | F31: =IF('Week B - Template'!F31="","",'Week B - Template'!F31) -> 9F/It | G31: =IF('Week B - Template'!G31="","",'Week B - Template'!G31) -> 12/Cs1 | H31: =IF('Week B - Template'!H31="","",'Week B - Template'!H31) | I31: =IF('Week B - Template'!I31="","",'Week B - Template'!I31) -> 11B/It
C32: Break 2
C33: Period 5 | D33: =IF('Week B - Template'!D33="","",'Week B - Template'!D33) | E33: =IF('Week B - Template'!E33="","",'Week B - Template'!E33) -> 8D/It | F33: =IF('Week B - Template'!F33="","",'Week B - Template'!F33) -> 11B/It | G33: =IF('Week B - Template'!G33="","",'Week B - Template'!G33) -> 7B/Cs | H33: =IF('Week B - Template'!H33="","",'Week B - Template'!H33) -> 10D/Bs | I33: =IF('Week B - Template'!I33="","",'Week B - Template'!I33)
C34: Period 6 | D34: =IF('Week B - Template'!D34="","",'Week B - Template'!D34) -> 7B/Cs | E34: =IF('Week B - Template'!E34="","",'Week B - Template'!E34) | F34: =IF('Week B - Template'!F34="","",'Week B - Template'!F34) -> 13/It2 | G34: =IF('Week B - Template'!G34="","",'Week B - Template'!G34) -> 9E/It | H34: =IF('Week B - Template'!H34="","",'Week B - Template'!H34) -> 11C/Bs | I34: =IF('Week B - Template'!I34="","",'Week B - Template'!I34) -> 8C/Bs
B36: 46289 | C36: Registration
C37: Period 1 | D37: =IF('Week B - Template'!D37="","",'Week B - Template'!D37) | E37: =IF('Week B - Template'!E37="","",'Week B - Template'!E37) -> 12/Cs1 | F37: =IF('Week B - Template'!F37="","",'Week B - Template'!F37) -> 8D/It | G37: =IF('Week B - Template'!G37="","",'Week B - Template'!G37) -> 11B/It | H37: =IF('Week B - Template'!H37="","",'Week B - Template'!H37) -> 7B/Cs | I37: =IF('Week B - Template'!I37="","",'Week B - Template'!I37)
C38: Period 2 | D38: =IF('Week B - Template'!D38="","",'Week B - Template'!D38) -> 11B/It | E38: =IF('Week B - Template'!E38="","",'Week B - Template'!E38) | F38: =IF('Week B - Template'!F38="","",'Week B - Template'!F38) -> 10D/Bs | G38: =IF('Week B - Template'!G38="","",'Week B - Template'!G38) -> 13/It2 | H38: =IF('Week B - Template'!H38="","",'Week B - Template'!H38) -> 9E/It | I38: =IF('Week B - Template'!I38="","",'Week B - Template'!I38) -> 11C/Bs
C39: Break 1
C40: Period 3 | D40: =IF('Week B - Template'!D40="","",'Week B - Template'!D40) -> 13/It2 | E40: =IF('Week B - Template'!E40="","",'Week B - Template'!E40) -> 9E/It | F40: =IF('Week B - Template'!F40="","",'Week B - Template'!F40) | G40: =IF('Week B - Template'!G40="","",'Week B - Template'!G40) -> 8C/Bs | H40: =IF('Week B - Template'!H40="","",'Week B - Template'!H40) -> 10E/Cs | I40: =IF('Week B - Template'!I40="","",'Week B - Template'!I40) -> 7A/Cs
C41: Period 4 | D41: =IF('Week B - Template'!D41="","",'Week B - Template'!D41) -> 8C/Bs | E41: =IF('Week B - Template'!E41="","",'Week B - Template'!E41) -> 10E/Cs | F41: =IF('Week B - Template'!F41="","",'Week B - Template'!F41) -> 7A/Cs | G41: =IF('Week B - Template'!G41="","",'Week B - Template'!G41) | H41: =IF('Week B - Template'!H41="","",'Week B - Template'!H41) -> 12/Cs1 | I41: =IF('Week B - Template'!I41="","",'Week B - Template'!I41) -> 8D/It
C42: Break 2
C43: Period 5 | D43: =IF('Week B - Template'!D43="","",'Week B - Template'!D43) -> 9F/It | E43: =IF('Week B - Template'!E43="","",'Week B - Template'!E43) -> 12/Cs1 | F43: =IF('Week B - Template'!F43="","",'Week B - Template'!F43) -> 8D/It | G43: =IF('Week B - Template'!G43="","",'Week B - Template'!G43) -> 11B/It | H43: =IF('Week B - Template'!H43="","",'Week B - Template'!H43) | I43: =IF('Week B - Template'!I43="","",'Week B - Template'!I43) -> 10D/Bs
C44: Period 6 | D44: =IF('Week B - Template'!D44="","",'Week B - Template'!D44) | E44: =IF('Week B - Template'!E44="","",'Week B - Template'!E44) -> 7B/Cs | F44: =IF('Week B - Template'!F44="","",'Week B - Template'!F44) -> 10D/Bs | G44: =IF('Week B - Template'!G44="","",'Week B - Template'!G44) -> 13/It2 | H44: =IF('Week B - Template'!H44="","",'Week B - Template'!H44) -> 9E/It | I44: =IF('Week B - Template'!I44="","",'Week B - Template'!I44)
...

Sheet (A) Sept 28th - Oct 2nd
B1: WEEK A | D1: N21 | E1: N22 | F1: N23 | G1: N24 | H1: N25 | I1: N26
C2: Teacher | D2: J Barnes | E2: A Okafor | F2: - | G2: S Whitfield | H2: M Devlin | I2: —
C3: No of PCs | D3: 30 | E3: 28 | F3: 15 | G3: 32 | H3: 24 | I3: 12
C4: Telephone | D4: 2101 | E4: 2102 | F4: 0x10 | G4: 2104 | H4: 2105 | I4: 2106
B6: 46293 | C6: Registration
C7: Period 1 | D7: =IF('Week A - Template'!D7="","",'Week A - Template'!D7) -> 10E/Cs | E7: =IF('Week A - Template'!E7="","",'Week A - Template'!E7) -> 7A/Cs | F7: =IF('Week A - Template'!F7="","",'Week A - Template'!F7) -> 9F/It | G7: =IF('Week A - Template'!G7="","",'Week A - Template'!G7) -> 12/Cs1 | H7: =IF('Week A - Template'!H7="","",'Week A - Template'!H7) | I7: =IF('Week A - Template'!I7="","",'Week A - Template'!I7) -> 11B/It
C8: Period 2 | D8: =IF('Week A - Template'!D8="","",'Week A - Template'!D8) | E8: =IF('Week A - Template'!E8="","",'Week A - Template'!E8) -> 8D/It | F8: =IF('Week A - Template'!F8="","",'Week A - Template'!F8) -> 11B/It | G8: =IF('Week A - Template'!G8="","",'Week A - Template'!G8) -> 7B/Cs | H8: =IF('Week A - Template'!H8="","",'Week A - Template'!H8) -> 10D/Bs | I8: =IF('Week A - Template'!I8="","",'Week A - Template'!I8)
C9: Break 1
C10: Period 3 | D10: =IF('Week A - Template'!D10="","",'Week A - Template'!D10) -> 7B/Cs | E10: =IF('Week A - Template'!E10="","",'Week A - Template'!E10) | F10: =IF('Week A - Template'!F10="","",'Week A - Template'!F10) -> 13/It2 | G10: =IF('Week A - Template'!G10="","",'Week A - Template'!G10) -> 9E/It | H10: =IF('Week A - Template'!H10="","",'Week A - Template'!H10) -> 11C/Bs | I10: =IF('Week A - Template'!I10="","",'Week A - Template'!I10) -> 8C/Bs
C11: Period 4 | D11: =IF('Week A - Template'!D11="","",'Week A - Template'!D11) -> 9E/It | E11: =IF('Week A - Template'!E11="","",'Week A - Template'!E11) -> 11C/Bs | F11: =IF('Week A - Template'!F11="","",'Week A - Template'!F11) | G11: =IF('Week A - Template'!G11="","",'Week A - Template'!G11) -> 10E/Cs | H11: =IF('Week A - Template'!H11="","",'Week A - Template'!H11) -> 7A/Cs | I11: =IF('Week A - Template'!I11="","",'Week A - Template'!I11) -> 9F/It
C12: Break 2
C13: Period 5 | D13: =IF('Week A - Template'!D13="","",'Week A - Template'!D13) -> 10E/Cs | E13: =IF('Week A - Template'!E13="","",'Week A - Template'!E13) -> 7A/Cs | F13: =IF('Week A - Template'!F13="","",'Week A - Template'!F13) -> 9F/It | G13: =IF('Week A - Template'!G13="","",'Week A - Template'!G13) | H13: =IF('Week A - Template'!H13="","",'Week A - Template'!H13) -> 8D/It | I13: =IF('Week A - Template'!I13="","",'Week A - Template'!I13) -> 11B/It
C14: Period 6 | D14: =IF('Week A - Template'!D14="","",'Week A - Template'!D14) -> 12/Cs1 | E14: =IF('Week A - Template'!E14="","",'Week A - Template'!E14) -> 8D/It | F14: =IF('Week A - Template'!F14="","",'Week A - Template'!F14) -> 11B/It | G14: =IF('Week A - Template'!G14="","",'Week A - Template'!G14) -> 7B/Cs | H14: =IF('Week A - Template'!H14="","",'Week A - Template'!H14) | I14: =IF('Week A - Template'!I14="","",'Week A - Template'!I14) -> 13/It2
B16: 46294 | C16: Registration
C17: Period 1 | D17: =IF('Week A - Template'!D17="","",'Week A - Template'!D17) -> 8C/Bs | E17: =IF('Week A - Template'!E17="","",'Week A - Template'!E17) -> 10E/Cs | F17: =IF('Week A - Template'!F17="","",'Week A - Template'!F17) -> 7A/Cs | G17: =IF('Week A - Template'!G17="","",'Week A - Template'!G17) | H17: =IF('Week A - Template'!H17="","",'Week A - Template'!H17) -> 12/Cs1 | I17: =IF('Week A - Template'!I17="","",'Week A - Template'!I17) -> 8D/It
C18: Period 2 | D18: =IF('Week A - Template'!D18="","",'Week A - Template'!D18) -> 9F/It | E18: =IF('Week A - Template'!E18="","",'Week A - Template'!E18) -> 12/Cs1 | F18: =IF('Week A - Template'!F18="","",'Week A - Template'!F18) -> 8D/It | G18: =IF('Week A - Template'!G18="","",'Week A - Template'!G18) -> 11B/It | H18: =IF('Week A - Template'!H18="","",'Week A - Template'!H18) | I18: =IF('Week A - Template'!I18="","",'Week A - Template'!I18) -> 10D/Bs
C19: Break 1
C20: Period 3 | D20: =IF('Week A - Template'!D20="","",'Week A - Template'!D20) | E20: =IF('Week A - Template'!E20="","",'Week A - Template'!E20) -> 7B/Cs | F20: =IF('Week A - Template'!F20="","",'Week A - Template'!F20) -> 10D/Bs | G20: =IF('Week A - Template'!G20="","",'Week A - Template'!G20) -> 13/It2 | H20: =IF('Week A - Template'!H20="","",'Week A - Template'!H20) -> 9E/It | I20: =IF('Week A - Template'!I20="","",'Week A - Template'!I20)
C21: Period 4 | D21: =IF('Week A - Template'!D21="","",'Week A - Template'!D21) -> 13/It2 | E21: =IF('Week A - Template'!E21="","",'Week A - Template'!E21) | F21: =IF('Week A - Template'!F21="","",'Week A - Template'!F21) -> 11C/Bs | G21: =IF('Week A - Template'!G21="","",'Week A - Template'!G21) -> 8C/Bs | H21: =IF('Week A - Template'!H21="","",'Week A - Template'!H21) -> 10E/Cs | I21: =IF('Week A - Template'!I21="","",'Week A - Template'!I21) -> 7A/Cs
C22: Break 2
C23: Period 5 | D23: =IF('Week A - Template'!D23="","",'Week A - Template'!D23) -> 8C/Bs | E23: =IF('Week A - Template'!E23="","",'Week A - Template'!E23) -> 10E/Cs | F23: =IF('Week A - Template'!F23="","",'Week A - Template'!F23) | G23: =IF('Week A - Template'!G23="","",'Week A - Template'!G23) -> 9F/It | H23: =IF('Week A - Template'!H23="","",'Week A - Template'!H23) -> 12/Cs1 | I23: =IF('Week A - Template'!I23="","",'Week A - Template'!I23) -> 8D/It
C24: Period 6 | D24: =IF('Week A - Template'!D24="","",'Week A - Template'!D24) -> 9F/It | E24: =IF('Week A - Template'!E24="","",'Week A - Template'!E24) -> 12/Cs1 | F24: =IF('Week A - Template'!F24="","",'Week A - Template'!F24) -> 8D/It | G24: =IF('Week A - Template'!G24="","",'Week A - Template'!G24) | H24: =IF('Week A - Template'!H24="","",'Week A - Template'!H24) -> 7B/Cs | I24: =IF('Week A - Template'!I24="","",'Week A - Template'!I24) -> 10D/Bs
B26: 46295 | C26: Registration
C27: Period 1 | D27: =IF('Week A - Template'!D27="","",'Week A - Template'!D27) -> 11C/Bs | E27: =IF('Week A - Template'!E27="","",'Week A - Template'!E27) -> 8C/Bs | F27: =IF('Week A - Template'!F27="","",'Week A - Template'!F27) | G27: =IF('Week A - Template'!G27="","",'Week A - Template'!G27) -> 7A/Cs | H27: =IF('Week A - Template'!H27="","",'Week A - Template'!H27) -> 9F/It | I27: =IF('Week A - Template'!I27="","",'Week A - Template'!I27) -> 12/Cs1
C28: Period 2 | D28: =IF('Week A - Template'!D28="","",'Week A - Template'!D28) -> 7A/Cs | E28: =IF('Week A - Template'!E28="","",'Week A - Template'!E28) -> 9F/It | F28: =IF('Week A - Template'!F28="","",'Week A - Template'!F28) -> 12/Cs1 | G28: =IF('Week A - Template'!G28="","",'Week A - Template'!G28) | H28: =IF('Week A - Template'!H28="","",'Week A - Template'!H28) -> 11B/It | I28: =IF('Week A - Template'!I28="","",'Week A - Template'!I28) -> 7B/Cs
C29: Break 1
C30: Period 3 | D30: =IF('Week A - Template'!D30="","",'Week A - Template'!D30) -> 8D/It | E30: =IF('Week A - Template'!E30="","",'Week A - Template'!E30) -> 11B/It | F30: =IF('Week A - Template'!F30="","",'Week A - Template'!F30) -> 7B/Cs | G30: =IF('Week A - Template'!G30="","",'Week A - Template'!G30) -> 10D/Bs | H30: =IF('Week A - Template'!H30="","",'Week A - Template'!H30) | I30: =IF('Week A - Template'!I30="","",'Week A - Template'!I30) -> 9E/It
C31: Period 4 | D31: =IF('Week A - Template'!D31="","",'Week A - Template'!D31) | E31: =IF('Week A - Template'!E31="","",'Week A - Template'!E31) -> 13/It2 | F31: =IF('Week A - Template'!F31="","",'Week A - Template'!F31) -> 9E/It | G31: =IF('Week A - Template'!G31="","",'Week A - Template'!G31) -> 11C/Bs | H31: =IF('Week A - Template'!H31="","",'Week A - Template'!H31) -> 8C/Bs | I31: =IF('Week A - Template'!I31="","",'Week A - Template'!I31)
C32: Break 2
C33: Period 5 | D33: =IF('Week A - Template'!D33="","",'Week A - Template'!D33) -> 11C/Bs | E33: =IF('Week A - Template'!E33="","",'Week A - Template'!E33) | F33: =IF('Week A - Template'!F33="","",'Week A - Template'!F33) -> 10E/Cs | G33: =IF('Week A - Template'!G33="","",'Week A - Template'!G33) -> 7A/Cs | H33: =IF('Week A - Template'!H33="","",'Week A - Template'!H33) -> 9F/It | I33: =IF('Week A - Template'!I33="","",'Week A - Template'!I33) -> 12/Cs1
C34: Period 6 | D34: =IF('Week A - Template'!D34="","",'Week A - Template'!D34) -> 7A/Cs | E34: =IF('Week A - Template'!E34="","",'Week A - Template'!E34) -> 9F/It | F34: =IF('Week A - Template'!F34="","",'Week A - Template'!F34) | G34: =IF('Week A - Template'!G34="","",'Week A - Template'!G34) -> 8D/It | H34: =IF('Week A - Template'!H34="","",'Week A - Template'!H34) -> 11B/It | I34: =IF('Week A - Template'!I34="","",'Week A - Template'!I34) -> 7B/Cs
B36: 46296 | C36: Registration
C37: Period 1 | D37: =IF('Week A - Template'!D37="","",'Week A - Template'!D37) -> 9E/It | E37: =IF('Week A - Template'!E37="","",'Week A - Template'!E37) -> - | F37: =IF('Week A - Template'!F37="","",'Week A - Template'!F37) -> 8C/Bs | G37: =IF('Week A - Template'!G37="","",'Week A - Template'!G37) -> 10E/Cs | H37: =IF('Week A - Template'!H37="","",'Week A - Template'!H37) -> 7A/Cs | I37: =IF('Week A - Template'!I37="","",'Week A - Template'!I37) -> 9F/It
C38: Period 2 | D38: =IF('Week A - Template'!D38="","",'Week A - Template'!D38) -> 10E/Cs | E38: =IF('Week A - Template'!E38="","",'Week A - Template'!E38) -> 7A/Cs | F38: =IF('Week A - Template'!F38="","",'Week A - Template'!F38) | G38: =IF('Week A - Template'!G38="","",'Week A - Template'!G38) -> 12/Cs1 | H38: =IF('Week A - Template'!H38="","",'Week A - Template'!H38) -> 8D/It | I38: =IF('Week A - Template'!I38="","",'Week A - Template'!I38) -> 11B/It
C39: Break 1
C40: Period 3 | D40: =IF('Week A - Template'!D40="","",'Week A - Template'!D40) -> 12/Cs1 | E40: =IF('Week A - Template'!E40="","",'Week A - Template'!E40) -> 8D/It | F40: =IF('Week A - Template'!F40="","",'Week A - Template'!F40) -> 11B/It | G40: =IF('Week A - Template'!G40="","",'Week A - Template'!G40) | H40: =IF('Week A - Template'!H40="","",'Week A - Template'!H40) -> 10D/Bs | I40: =IF('Week A - Template'!I40="","",'Week A - Template'!I40) -> 13/It2
C41: Period 4 | D41: =IF('Week A - Template'!D41="","",'Week A - Template'!D41) -> 7B/Cs | E41: =IF('Week A - Template'!E41="","",'Week A - Template'!E41) -> 10D/Bs | F41: =IF('Week A - Template'!F41="","",'Week A - Template'!F41) -> 13/It2 | G41: =IF('Week A - Template'!G41="","",'Week A - Template'!G41) -> 9E/It | H41: =IF('Week A - Template'!H41="","",'Week A - Template'!H41) | I41: =IF('Week A - Template'!I41="","",'Week A - Template'!I41) -> 8C/Bs
C42: Break 2
C43: Period 5 | D43: =IF('Week A - Template'!D43="","",'Week A - Template'!D43) | E43: =IF('Week A - Template'!E43="","",'Week A - Template'!E43) -> 11C/Bs | F43: =IF('Week A - Template'!F43="","",'Week A - Template'!F43) -> 8C/Bs | G43: =IF('Week A - Template'!G43="","",'Week A - Template'!G43) -> 10E/Cs | H43: =IF('Week A - Template'!H43="","",'Week A - Template'!H43) -> 7A/Cs | I43: =IF('Week A - Template'!I43="","",'Week A - Template'!I43)
C44: Period 6 | D44: =IF('Week A - Template'!D44="","",'Week A - Template'!D44) -> 10E/Cs | E44: =IF('Week A - Template'!E44="","",'Week A - Template'!E44) | F44: =IF('Week A - Template'!F44="","",'Week A - Template'!F44) -> 9F/It | G44: =IF('Week A - Template'!G44="","",'Week A - Template'!G44) -> 12/Cs1 | H44: =IF('Week A - Template'!H44="","",'Week A - Template'!H44) -> 8D/It | I44: =IF('Week A - Template'!I44="","",'Week A - Template'!I44) -> 11B/It
...

Sheet (B) October 5th - 9th
B1: WEEK B | D1: N21 | E1: N22 | F1: N23 | G1: N24 | H1: N25 | I1: N26
C2: Teacher | D2: J Barnes | E2: A Okafor | F2: - | G2: S Whitfield | H2: M Devlin | I2: —
C3: No of PCs | D3: 30 | E3: 28 | F3: 15 | G3: 32 | H3: 24 | I3: 12
C4: Telephone | D4: 2101 | E4: 2102 | F4: 0x10 | G4: 2104 | H4: 2105 | I4: 2106
B6: 46300 | C6: Registration
C7: Period 1 | D7: =IF('Week B - Template'!D7="","",'Week B - Template'!D7) -> 11B/It | E7: =IF('Week B - Template'!E7="","",'Week B - Template'!E7) -> 7B/Cs | F7: =IF('Week B - Template'!F7="","",'Week B - Template'!F7) -> 10D/Bs | G7: =IF('Week B - Template'!G7="","",'Week B - Template'!G7) | H7: =IF('Week B - Template'!H7="","",'Week B - Template'!H7) -> 9E/It | I7: =IF('Week B - Template'!I7="","",'Week B - Template'!I7) -> 11C/Bs
C8: Period 2 | D8: =IF('Week B - Template'!D8="","",'Week B - Template'!D8) -> 13/It2 | E8: =IF('Week B - Template'!E8="","",'Week B - Template'!E8) -> 9E/It | F8: =IF('Week B - Template'!F8="","",'Week B - Template'!F8) -> 11C/Bs | G8: =IF('Week B - Template'!G8="","",'Week B - Template'!G8) -> 8C/Bs | H8: =IF('Week B - Template'!H8="","",'Week B - Template'!H8) | I8: =IF('Week B - Template'!I8="","",'Week B - Template'!I8) -> 7A/Cs
C9: Break 1
C10: Period 3 | D10: =IF('Week B - Template'!D10="","",'Week B - Template'!D10) | E10: =IF('Week B - Template'!E10="","",'Week B - Template'!E10) -> 10E/Cs | F10: =IF('Week B - Template'!F10="","",'Week B - Template'!F10) -> 7A/Cs | G10: =IF('Week B - Template'!G10="","",'Week B - Template'!G10) -> 9F/It | H10: =IF('Week B - Template'!H10="","",'Week B - Template'!H10) -> 12/Cs1 | I10: =IF('Week B - Template'!I10="","",'Week B - Template'!I10)
C11: Period 4 | D11: =IF('Week B - Template'!D11="","",'Week B - Template'!D11) -> 9F/It | E11: =IF('Week B - Template'!E11="","",'Week B - Template'!E11) | F11: =IF('Week B - Template'!F11="","",'Week B - Template'!F11) -> 8D/It | G11: =IF('Week B - Template'!G11="","",'Week B - Template'!G11) -> 11B/It | H11: =IF('Week B - Template'!H11="","",'Week B - Template'!H11) -> 7B/Cs | I11: =IF('Week B - Template'!I11="","",'Week B - Template'!I11) -> 10D/Bs
C12: Break 2
